Workbook
Name DENUMIRE: #REF!
Name Domain: [1]Liste!$B$2:$B$5

Sheet Centralizator FO Proconect
A1: Ticket ID | B1: Judet | C1: Localitate | D1: Solicitare interventie | E1: Finalizare incident | F1: Descriere Lucrare | G1: BOQ item list | H1: Unit | I1: BOQ quant/item | J1: Services & material price EUR | K1: Total material EUR | L1: Observatii Pro Conect
A2: IUNIE 2026 | K2: =SUBTOTAL(9,K3:K21) -> 2811
A3: PBM 64790 | B3: ALBA | C3: CUT | D3: 46179 | E3: 46179 | F3: REPLANTAT 1 STALP DE LEMN | G3: Inlocuire stalp de lemn/compozit incl preluarea stalpului existent (servicii complete, transport, consumabile); Replacement of wooden / composite pole incl. removal of existing pole (full services + transport); incl. transport, consumables | H3: buc | I3: 1 | J3: =VLOOKUP(G3,'Anexa 3'!B$3:D$30,3,0) -> 75 | K3: =I3*J3 -> 75 | L3: ok
A4: PBM 65455 | B4: ALBA | C4: JIDVEI-CAPALNA | D4: 46190 | E4: 46190 | F4: Repozitionat fo pe 4 stalpi | G4: SP FO CW 6 - Interventie Manipulare Cablu | H4: buc | I4: 2 | J4: =VLOOKUP(G4,'Anexa 3'!B$3:D$30,3,0) -> 85 | K4: =I4*J4 -> 170 | L4: ok
A5: PBM 64509 | B5: ALBA | C5: BLAJ | D5: 46175 | E5: 46176 | F5: Inlocuit capac spart in carosabil | G5: SP FO CW 1 - Interventie Minora Infrastructura Subterana | H5: buc | I5: 1 | J5: =VLOOKUP(G5,'Anexa 3'!B$3:D$30,3,0) -> 85 | K5: =I5*J5 -> 85 | L5: ok
A6: PBM 64551 | B6: ALBA | C6: SEBES | D6: 46176 | E6: 46176 | F6: INLOCUIT 1 STALP DE COMPOZIT (7m) | G6: Inlocuire stalp de lemn/compozit incl preluarea stalpului existent (servicii complete, transport, consumabile); Replacement of wooden / composite pole incl. removal of existing pole (full services + transport); incl. transport, consumables | H6: buc | I6: 1 | J6: =VLOOKUP(G6,'Anexa 3'!B$3:D$30,3,0) -> 75 | K6: =I6*J6 -> 75 | L6: ok
A7: PBM 64772 | B7: ALBA | C7: SONA | D7: 46184 | E7: 46189 | F7: DESFINTAT 1 STALP DE LEMN ;2 armorozi | G7: Demontare stalp de lemn | H7: buc | I7: 1 | J7: =VLOOKUP(G7,'Anexa 3'!B$3:D$30,3,0) -> 70 | K7: =I7*J7 -> 70 | L7: Material custodie
A8: PBM 64773 | B8: ALBA | C8: SONA | D8: 46184 | E8: 46189 | F8: INLOCUIT 11 STALPI (10-7M 1-8M); INSTALAT FO PE 3 STALPI | G8: Inlocuire stalp de lemn/compozit incl preluarea stalpului existent (servicii complete, transport, consumabile); Replacement of wooden / composite pole incl. removal of existing pole (full services + transport); incl. transport, consumables | H8: buc | I8: 11 | J8: =VLOOKUP(G8,'Anexa 3'!B$3:D$30,3,0) -> 75 | K8: =I8*J8 -> 825 | L8: Material custodie
A9: PBM 64773 | B9: ALBA | C9: SONA | D9: 46184 | E9: 46189 | F9: INLOCUIT 11 STALPI (10-7M 1-8M); INSTALAT FO PE 3 STALPI | G9: SP FO CW 6 - Interventie Manipulare Cablu | H9: buc | I9: 1 | J9: =VLOOKUP(G9,'Anexa 3'!B$3:D$30,3,0) -> 85 | K9: =I9*J9 -> 85 | L9: Material custodie
A10: PBM 64779 | B10: ALBA | C10: SANCEL | D10: 46184 | E10: 46189 | F10: inlocuit 2 stalpi de compozit (7m) | G10: Inlocuire stalp de lemn/compozit incl preluarea stalpului existent (servicii complete, transport, consumabile); Replacement of wooden / composite pole incl. removal of existing pole (full services + transport); incl. transport, consumables | H10: buc | I10: 2 | J10: =VLOOKUP(G10,'Anexa 3'!B$3:D$30,3,0) -> 75 | K10: =I10*J10 -> 150 | L10: Material custodie
A11: PBM 64860 | B11: ALBA | C11: SEBES | D11: 46183 | E11: 46190 | F11: Asistentă 2 zile Z1 - 2 persoane - 3 ore Z2 - 2 persoane- 4 ore | G11: ='Anexa 3'!B25 -> SP FO CW 6 - Interventie Manipulare Cablu | H11: buc | I11: 1 | J11: =VLOOKUP(G11,'Anexa 3'!B$3:D$30,3,0) -> 85 | K11: =I11*J11 -> 85 | L11: Material custodie
A12: PBM 65409 | B12: ALBA | C12: VINTU DE JOS | D12: 46196 | E12: 46197 | F12: REPOZITIOANA 650M FO AUTOPURTATA ;DESFINTAT 2 STALPI DE LEMN ;INSTALAT 1 STALP DE COMPOZIT (8M);INSTALAT 1 ANCORA CU TOTUL | G12: SP FO CW 6 - Interventie Manipulare Cablu | H12: buc | I12: 4 | J12: =VLOOKUP(G12,'Anexa 3'!B$3:D$30,3,0) -> 85 | K12: =I12*J12 -> 340 | L12: Material custodie
A13: PBM 65409 | B13: ALBA | C13: VINTU DE JOS | D13: 46196 | E13: 46197 | F13: REPOZITIOANA 650M FO AUTOPURTATA ;DESFINTAT 2 STALPI DE LEMN ;INSTALAT 1 STALP DE COMPOZIT (8M);INSTALAT 1 ANCORA CU TOTUL | G13: Demontare stalp de lemn | H13: buc | I13: 2 | J13: =VLOOKUP(G13,'Anexa 3'!B$3:D$30,3,0) -> 70 | K13: =I13*J13 -> 140 | L13: Material custodie
A14: PBM 65409 | B14: ALBA | C14: VINTU DE JOS | D14: 46196 | E14: 46197 | F14: REPOZITIOANA 650M FO AUTOPURTATA ;DESFINTAT 2 STALPI DE LEMN ;INSTALAT 1 STALP DE COMPOZIT (8M);INSTALAT 1 ANCORA CU TOTUL | G14: Inlocuire stalp de lemn/compozit incl preluarea stalpului existent (servicii complete, transport, consumabile); Replacement of wooden / composite pole incl. removal of existing pole (full services + transport); incl. transport, consumables | H14: buc | I14: 1 | J14: =VLOOKUP(G14,'Anexa 3'!B$3:D$30,3,0) -> 75 | K14: =I14*J14 -> 75
A15: PBM 65409 | B15: ALBA | C15: VINTU DE JOS | D15: 46196 | E15: 46197 | F15: REPOZITIOANA 650M FO AUTOPURTATA ;DESFINTAT 2 STALPI DE LEMN ;INSTALAT 1 STALP DE COMPOZIT (8M);INSTALAT 1 ANCORA CU TOTUL | G15: ANCORA | H15: buc | I15: 1 | J15: 20 | K15: =I15*J15 -> 20 | L15: Material custodie
A16: PBM 65484 | B16: ALBA | C16: PETRESTI | D16: 46197 | E16: 46197 | F16: Inlocuit 1 stalp de compozit (7m) | G16: Inlocuire stalp de lemn/compozit incl preluarea stalpului existent (servicii complete, transport, consumabile); Replacement of wooden / composite pole incl. removal of existing pole (full services + transport); incl. transport, consumables | H16: buc | I16: 1 | J16: =VLOOKUP(G16,'Anexa 3'!B$3:D$30,3,0) -> 75 | K16: =I16*J16 -> 75 | L16: Material custodie
A17: PBM 65614 | B17: ALBA | C17: Sona - Ranmanmiclaus | D17: 46191 | E17: 46191 | F17: instalat 7 stalpi de compozit | G17: Inlocuire stalp de lemn/compozit incl preluarea stalpului existent (servicii complete, transport, consumabile); Replacement of wooden / composite pole incl. removal of existing pole (full services + transport); incl. transport, consumables | H17: buc | I17: 7 | J17: =VLOOKUP(G17,'Anexa 3'!B$3:D$30,3,0) -> 75 | K17: =I17*J17 -> 525 | L17: Material custodie
F18: 4 ARMOROZI | G18: ='Anexa 3'!B113 -> Monting kit for cable on pole/wall - material - armorod | H18: buc | I18: 4 | J18: ='Anexa 3'!D113 -> 4 | K18: =I18*J18 -> 16 | L18: Material custodie
L19: Material custodie
L20: Material custodie
L21: Material custodie
G22: Sant pentru instalare tevi direct in pamant (servicii complete, transport, consumabile); Ditch for installing pipes underground (complete services; transport, consumables) | H22: m3 | I22: 0 | J22: =VLOOKUP(G22,'Anexa 3'!B$3:D$30,3,0) -> 8.5 | K22: =I22*J22 -> 0
G23: Sant pentru instalare tevi direct in pamant (servicii complete, transport, consumabile); Ditch for installing pipes underground (complete services; transport, consumables) | H23: m3 | I23: 0 | J23: =VLOOKUP(G23,'Anexa 3'!B$3:D$30,3,0) -> 8.5 | K23: =I23*J23 -> 0
G25: TOTAL RON FARA TVA | K25: =K2*H27 -> 13990.347
G27: Curs BNR 05.03.2025 | H27: 4.977
A28: Antreprenor | F28: Subantreprenor
A29: SC Pro Conect SRL | F29: SC TEDAL TELECOMMUNICATION SRL

Sheet Anexa 3
A1: ANEXA 3
A2: nr.crt. | B2: descriere serviciu | C2: UM | D2: pret euro fara tva | E2: cant | F2: total euro fara tva
A3: 1 | B3: On Site FO Measurements for FO Incident Diagnose | C3: buc | D3: 80 | F3: =D3*E3 -> 0
A4: 2 | B4: Complete services On-site repairs only (ODF, patch); all services included, except those considered as Specific Works (listed under); The Specific Works items (7-16) will be used in the BoQ on top of Service Package (2-6) if required. | C4: buc | D4: 190 | F4: =D4*E4 -> 0
A5: 3 | B5: Complete services Aerial repairs (no new cable required); all services included, except those considered as Specific Works (listed under); The Specific Works items (7-16) will be used in the BoQ on top of Service Package (2-6) if required. | C5: buc | D5: 240 | F5: =D5*E5 -> 0
A6: 4 | B6: Complete services Aerial repairs (<200m new cable required); all services included, except those considered as Specific Works (listed under); The Specific Works items (10-23) will be used in the BoQ on top of Service Package (1-7) if required. | C6: buc | D6: 250 | F6: =D6*E6 -> 0
A7: 5 | B7: Complete services Aerial, Capital repairs (>200m new cable required); all services included, except those considered as Specific Works (listed under); The Specific Works items (7-16) will be used in the BoQ on top of Service Package (2-6) if required. | C7: buc | D7: 270 | F7: =D7*E7 -> 0
A8: 6 | B8: Complete services Underground repairs (up to max 200m cable required); all services included, except those considered as Specific Works (listed under); The Specific Works items (7-16) will be used in the BoQ on top of Service Package (2-6) if required. | C8: buc | D8: 490 | F8: =D8*E8 -> 0
A9: 7 | B9: Complete services Underground, Capital repairs (>200m cable required); all services included, except those considered as Specific Works (listed under); The Specific Works items (7-16) will be used in the BoQ on top of Service Package (2-6) if required. | C9: buc | D9: 550 | F9: =D9*E9 -> 0
A10: 8 | B10: Forare orizontala dirijata (servicii complete, transport, consumabile) ; Guided horizontal drilling (full services + transport); incl. transport, consumables | C10: m | D10: 40 | F10: =D10*E10 -> 0
A11: 9 | B11: Forare orizontala nedirijata (servicii complete, transport, consumabile); Unguided horizontal drilling (full services + transport); incl. transport, consumables | C11: m | D11: 35 | F11: =D11*E11 -> 0
A12: 10 | B12: Inlocuire stalp de lemn/compozit incl preluarea stalpului existent (servicii complete, transport, consumabile); Replacement of wooden / composite pole incl. removal of existing pole (full services + transport); incl. transport, consumables | C12: buc | D12: 75 | F12: =D12*E12 -> 0
A13: 11 | B13: Instalare stalp (metalic sau de beton) in fundatie turnata (servicii complete, transport, consumabile); Pole installation (metal or concrete) in cast foundation (complete services; transport, consumables) | C13: buc | D13: 220 | F13: =D13*E13 -> 0
A14: 12 | B14: Refacere imbracaminte asfaltica (manopera)(servicii complete, transport, consumabile); Asphalt coatings (labor) (complete services; transport, consumables) | C14: mp | D14: 55 | F14: =D14*E14 -> 0
... A30: 28 | B30: Demontare stalp de lemn | C30: buc | D30: 70 | F30: =D30*E30 -> 0
A31: 29 | C31: buc | D31: 0 | F31: =D31*E31 -> 0
A32: 30 | C32: buc | D32: 0 | F32: =D32*E32 -> 0
A33: nr.crt. | B33: descriere material | C33: UM | D33: pret euro fara tva | E33: cant | F33: total euro fara tva
A34: 1 | B34: Patch 10m E 2000/APC-SC/APC, SM, SX | C34: buc | D34: 6.18 | F34: =D34*E34 -> 0
A35: 2 | B35: Patch 10m LC/APC-SC/APC, SM, SX | C35: buc | D35: 3.35 | F35: =D35*E35 -> 0
A36: 3 | B36: Patch 10m LC/PC-SC/APC, SM, SX | C36: buc | D36: 3.19 | F36: =D36*E36 -> 0
A37: 4 | B37: Patch 10m SC/APC-SC/APC, SM, SX | C37: buc | D37: 3.08 | F37: =D37*E37 -> 0
A38: 5 | B38: Patch 10m SC/PC-SC/APC, SM, SX, G.657A | C38: buc | D38: 3.08 | F38: =D38*E38 -> 0
A39: 6 | B39: Patch 15m E 2000/APC-LC/APC, SM, SX | C39: buc | D39: 6.92 | F39: =D39*E39 -> 0
A40: 7 | B40: Patch 15m E 2000/APC-SC/APC, SM, SX | C40: buc | D40: 6.7 | F40: =D40*E40 -> 0
A41: 8 | B41: Patch 20m E 2000/APC-LC/APC, SM, SX | C41: buc | D41: 7.44 | F41: =D41*E41 -> 0
A42: 9 | B42: Patch 20m E 2000/APC-SC/APC, SM, SX | C42: buc | D42: 7.34 | F42: =D42*E42 -> 0
A43: 10 | B43: Patch 3m E 2000/APC-E 2000/APC, SM, DX | C43: buc | D43: 16.6 | F43: =D43*E43 -> 0
A44: 11 | B44: Patch 3m E 2000/APC-E 2000/APC, SM, SX | C44: buc | D44: 8.29 | F44: =D44*E44 -> 0
A45: 12 | B45: Patch 3m E 2000-SC SM, DX | C45: buc | D45: 10.53 | F45: =D45*E45 -> 0
... A119: 86 | B119: Rubber band-3M - material | C119: buc | D119: 0.27 | F119: =D119*E119 -> 0
B120: Item description | C120: Unit
A121: 87 | B121: ODB - with 8 duplex mating adaptors+Splitter 1:8 | C121: buc
A122: 88 | B122: SOD.A2.1X8.250.2,5.NC.2,5.NC.IEEE.OR | C122: buc
A123: 89 | B123: SOD.A2.1X8.900.1,5.SA.0,75.SA.IEEE.OR | C123: buc
A124: 90 | B124: SOD.A2.1X2.250.2,5.NC.2,5.NC.IEEE.OR | C124: buc
A125: 91 | B125: SOD.A2.1X4.250.2,5.NC.2,5.NC.IEEE.OR | C125: buc
A126: 92 | B126: BLG MB-0813 96XG657A1 SP1351 GN(DPL/ROM) | C126: m
A127: 93 | B127: FAUA|FT|K0D1E0 48 (4x12) G.657A2 | C127: m
A128: 94 | B128: FAUA|FT|K0D1E0 96 (8x12) G.657A2 | C128: m
...
